[2025-03-12T04:42:40.545+0000] {local_task_job_runner.py:123} INFO - ::group::Pre task execution logs
[2025-03-12T04:42:40.581+0000] {taskinstance.py:2614} INFO - Dependencies all met for dep_context=non-requeueable deps ti=<TaskInstance: data_ingestion_gcs_dag.upload_gcs_2025_q4 manual__2025-03-12T04:42:07.897134+00:00 [queued]>
[2025-03-12T04:42:40.599+0000] {taskinstance.py:2614} INFO - Dependencies all met for dep_context=requeueable deps ti=<TaskInstance: data_ingestion_gcs_dag.upload_gcs_2025_q4 manual__2025-03-12T04:42:07.897134+00:00 [queued]>
[2025-03-12T04:42:40.600+0000] {taskinstance.py:2867} INFO - Starting attempt 1 of 2
[2025-03-12T04:42:40.624+0000] {taskinstance.py:2890} INFO - Executing <Task(PythonOperator): upload_gcs_2025_q4> on 2025-03-12 04:42:07.897134+00:00
[2025-03-12T04:42:40.636+0000] {warnings.py:112} WARNING - /home/***/.local/lib/python3.12/site-packages/***/task/task_runner/standard_task_runner.py:70: DeprecationWarning: This process (pid=1518) is multi-threaded, use of fork() may lead to deadlocks in the child.
  pid = os.fork()

[2025-03-12T04:42:40.639+0000] {standard_task_runner.py:72} INFO - Started process 1572 to run task
[2025-03-12T04:42:40.639+0000] {standard_task_runner.py:104} INFO - Running: ['***', 'tasks', 'run', 'data_ingestion_gcs_dag', 'upload_gcs_2025_q4', 'manual__2025-03-12T04:42:07.897134+00:00', '--job-id', '353', '--raw', '--subdir', 'DAGS_FOLDER/data_ingestion_gcs_dag.py', '--cfg-path', '/tmp/tmpjqafq0yn']
[2025-03-12T04:42:40.640+0000] {standard_task_runner.py:105} INFO - Job 353: Subtask upload_gcs_2025_q4
[2025-03-12T04:42:40.707+0000] {task_command.py:467} INFO - Running <TaskInstance: data_ingestion_gcs_dag.upload_gcs_2025_q4 manual__2025-03-12T04:42:07.897134+00:00 [running]> on host b0577ed9eb82
[2025-03-12T04:42:40.847+0000] {taskinstance.py:3134} INFO - Exporting env vars: AIRFLOW_CTX_DAG_OWNER='***' AIRFLOW_CTX_DAG_ID='data_ingestion_gcs_dag' AIRFLOW_CTX_TASK_ID='upload_gcs_2025_q4' AIRFLOW_CTX_EXECUTION_DATE='2025-03-12T04:42:07.897134+00:00' AIRFLOW_CTX_TRY_NUMBER='1' AIRFLOW_CTX_DAG_RUN_ID='manual__2025-03-12T04:42:07.897134+00:00'
[2025-03-12T04:42:40.850+0000] {logging_mixin.py:190} INFO - Task instance is in running state
[2025-03-12T04:42:40.852+0000] {logging_mixin.py:190} INFO -  Previous state of the Task instance: queued
[2025-03-12T04:42:40.853+0000] {logging_mixin.py:190} INFO - Current task name:upload_gcs_2025_q4 state:running start_date:2025-03-12 04:42:40.582386+00:00
[2025-03-12T04:42:40.853+0000] {logging_mixin.py:190} INFO - Dag name:data_ingestion_gcs_dag and current dag run status:running
[2025-03-12T04:42:40.854+0000] {taskinstance.py:732} INFO - ::endgroup::
[2025-03-12T04:42:41.089+0000] {taskinstance.py:3313} ERROR - Task failed with exception
Traceback (most recent call last):
  File "/home/airflow/.local/lib/python3.12/site-packages/airflow/models/taskinstance.py", line 768, in _execute_task
    result = _execute_callable(context=context, **execute_callable_kwargs)
             ^^^^^^^^^^^^^^^^^^^^^^^^^^^^^^^^^^^^^^^^^^^^^^^^^^^^^^^^^^^^^
  File "/home/airflow/.local/lib/python3.12/site-packages/airflow/models/taskinstance.py", line 734, in _execute_callable
    return ExecutionCallableRunner(
           ^^^^^^^^^^^^^^^^^^^^^^^^
  File "/home/airflow/.local/lib/python3.12/site-packages/airflow/utils/operator_helpers.py", line 252, in run
    return self.func(*args, **kwargs)
           ^^^^^^^^^^^^^^^^^^^^^^^^^^
  File "/home/airflow/.local/lib/python3.12/site-packages/airflow/models/baseoperator.py", line 424, in wrapper
    return func(self, *args, **kwargs)
           ^^^^^^^^^^^^^^^^^^^^^^^^^^^
  File "/home/airflow/.local/lib/python3.12/site-packages/airflow/operators/python.py", line 238, in execute
    return_value = self.execute_callable()
                   ^^^^^^^^^^^^^^^^^^^^^^^
  File "/home/airflow/.local/lib/python3.12/site-packages/airflow/operators/python.py", line 256, in execute_callable
    return runner.run(*self.op_args, **self.op_kwargs)
           ^^^^^^^^^^^^^^^^^^^^^^^^^^^^^^^^^^^^^^^^^^^
  File "/home/airflow/.local/lib/python3.12/site-packages/airflow/utils/operator_helpers.py", line 252, in run
    return self.func(*args, **kwargs)
           ^^^^^^^^^^^^^^^^^^^^^^^^^^
  File "/opt/airflow/dags/data_ingestion_gcs_dag.py", line 80, in upload_to_gcs
    blob.upload_from_filename(local_file)
  File "/usr/local/lib/python3.12/contextlib.py", line 81, in inner
    return func(*args, **kwds)
           ^^^^^^^^^^^^^^^^^^^
  File "/home/airflow/.local/lib/python3.12/site-packages/google/cloud/storage/blob.py", line 3006, in upload_from_filename
    self._handle_filename_and_upload(
  File "/home/airflow/.local/lib/python3.12/site-packages/google/cloud/storage/blob.py", line 2882, in _handle_filename_and_upload
    with open(filename, "rb") as file_obj:
         ^^^^^^^^^^^^^^^^^^^^
FileNotFoundError: [Errno 2] No such file or directory: '/opt/airflow/indego-trips-2025-q4.parquet'
[2025-03-12T04:42:41.118+0000] {logging_mixin.py:190} INFO - Task instance in failure state
[2025-03-12T04:42:41.119+0000] {logging_mixin.py:190} INFO - Task start:2025-03-12 04:42:40.582386+00:00 end:2025-03-12 04:42:41.117331+00:00 duration:0.534945
[2025-03-12T04:42:41.120+0000] {logging_mixin.py:190} INFO - Task:<Task(PythonOperator): upload_gcs_2025_q4> dag:<DAG: data_ingestion_gcs_dag> dagrun:<DagRun data_ingestion_gcs_dag @ 2025-03-12 04:42:07.897134+00:00: manual__2025-03-12T04:42:07.897134+00:00, state:running, queued_at: 2025-03-12 04:42:07.935918+00:00. externally triggered: True>
[2025-03-12T04:42:41.120+0000] {logging_mixin.py:190} INFO - Failure caused by [Errno 2] No such file or directory: '/opt/***/indego-trips-2025-q4.parquet'
[2025-03-12T04:42:41.121+0000] {taskinstance.py:1226} INFO - Marking task as UP_FOR_RETRY. dag_id=data_ingestion_gcs_dag, task_id=upload_gcs_2025_q4, run_id=manual__2025-03-12T04:42:07.897134+00:00, execution_date=20250312T044207, start_date=20250312T044240, end_date=20250312T044241
[2025-03-12T04:42:41.175+0000] {taskinstance.py:341} INFO - ::group::Post task execution logs
[2025-03-12T04:42:41.176+0000] {standard_task_runner.py:124} ERROR - Failed to execute job 353 for task upload_gcs_2025_q4 ([Errno 2] No such file or directory: '/opt/airflow/indego-trips-2025-q4.parquet'; 1572)
Traceback (most recent call last):
  File "/home/airflow/.local/lib/python3.12/site-packages/airflow/task/task_runner/standard_task_runner.py", line 117, in _start_by_fork
    ret = args.func(args, dag=self.dag)
          ^^^^^^^^^^^^^^^^^^^^^^^^^^^^^
  File "/home/airflow/.local/lib/python3.12/site-packages/airflow/cli/cli_config.py", line 49, in command
    return func(*args, **kwargs)
           ^^^^^^^^^^^^^^^^^^^^^
  File "/home/airflow/.local/lib/python3.12/site-packages/airflow/utils/cli.py", line 116, in wrapper
    return f(*args, **kwargs)
           ^^^^^^^^^^^^^^^^^^
  File "/home/airflow/.local/lib/python3.12/site-packages/airflow/cli/commands/task_command.py", line 483, in task_run
    task_return_code = _run_task_by_selected_method(args, _dag, ti)
                       ^^^^^^^^^^^^^^^^^^^^^^^^^^^^^^^^^^^^^^^^^^^^
  File "/home/airflow/.local/lib/python3.12/site-packages/airflow/cli/commands/task_command.py", line 256, in _run_task_by_selected_method
    return _run_raw_task(args, ti)
           ^^^^^^^^^^^^^^^^^^^^^^^
  File "/home/airflow/.local/lib/python3.12/site-packages/airflow/cli/commands/task_command.py", line 341, in _run_raw_task
    return ti._run_raw_task(
           ^^^^^^^^^^^^^^^^^
  File "/home/airflow/.local/lib/python3.12/site-packages/airflow/utils/session.py", line 97, in wrapper
    return func(*args, session=session, **kwargs)
           ^^^^^^^^^^^^^^^^^^^^^^^^^^^^^^^^^^^^^^
  File "/home/airflow/.local/lib/python3.12/site-packages/airflow/models/taskinstance.py", line 3006, in _run_raw_task
    return _run_raw_task(
           ^^^^^^^^^^^^^^
  File "/home/airflow/.local/lib/python3.12/site-packages/airflow/models/taskinstance.py", line 274, in _run_raw_task
    TaskInstance._execute_task_with_callbacks(
  File "/home/airflow/.local/lib/python3.12/site-packages/airflow/models/taskinstance.py", line 3161, in _execute_task_with_callbacks
    result = self._execute_task(context, task_orig)
             ^^^^^^^^^^^^^^^^^^^^^^^^^^^^^^^^^^^^^^
  File "/home/airflow/.local/lib/python3.12/site-packages/airflow/models/taskinstance.py", line 3185, in _execute_task
    return _execute_task(self, context, task_orig)
           ^^^^^^^^^^^^^^^^^^^^^^^^^^^^^^^^^^^^^^^
  File "/home/airflow/.local/lib/python3.12/site-packages/airflow/models/taskinstance.py", line 768, in _execute_task
    result = _execute_callable(context=context, **execute_callable_kwargs)
             ^^^^^^^^^^^^^^^^^^^^^^^^^^^^^^^^^^^^^^^^^^^^^^^^^^^^^^^^^^^^^
  File "/home/airflow/.local/lib/python3.12/site-packages/airflow/models/taskinstance.py", line 734, in _execute_callable
    return ExecutionCallableRunner(
           ^^^^^^^^^^^^^^^^^^^^^^^^
  File "/home/airflow/.local/lib/python3.12/site-packages/airflow/utils/operator_helpers.py", line 252, in run
    return self.func(*args, **kwargs)
           ^^^^^^^^^^^^^^^^^^^^^^^^^^
  File "/home/airflow/.local/lib/python3.12/site-packages/airflow/models/baseoperator.py", line 424, in wrapper
    return func(self, *args, **kwargs)
           ^^^^^^^^^^^^^^^^^^^^^^^^^^^
  File "/home/airflow/.local/lib/python3.12/site-packages/airflow/operators/python.py", line 238, in execute
    return_value = self.execute_callable()
                   ^^^^^^^^^^^^^^^^^^^^^^^
  File "/home/airflow/.local/lib/python3.12/site-packages/airflow/operators/python.py", line 256, in execute_callable
    return runner.run(*self.op_args, **self.op_kwargs)
           ^^^^^^^^^^^^^^^^^^^^^^^^^^^^^^^^^^^^^^^^^^^
  File "/home/airflow/.local/lib/python3.12/site-packages/airflow/utils/operator_helpers.py", line 252, in run
    return self.func(*args, **kwargs)
           ^^^^^^^^^^^^^^^^^^^^^^^^^^
  File "/opt/airflow/dags/data_ingestion_gcs_dag.py", line 80, in upload_to_gcs
    blob.upload_from_filename(local_file)
  File "/usr/local/lib/python3.12/contextlib.py", line 81, in inner
    return func(*args, **kwds)
           ^^^^^^^^^^^^^^^^^^^
  File "/home/airflow/.local/lib/python3.12/site-packages/google/cloud/storage/blob.py", line 3006, in upload_from_filename
    self._handle_filename_and_upload(
  File "/home/airflow/.local/lib/python3.12/site-packages/google/cloud/storage/blob.py", line 2882, in _handle_filename_and_upload
    with open(filename, "rb") as file_obj:
         ^^^^^^^^^^^^^^^^^^^^
FileNotFoundError: [Errno 2] No such file or directory: '/opt/airflow/indego-trips-2025-q4.parquet'
[2025-03-12T04:42:41.219+0000] {local_task_job_runner.py:266} INFO - Task exited with return code 1
[2025-03-12T04:42:41.282+0000] {taskinstance.py:3901} INFO - 0 downstream tasks scheduled from follow-on schedule check
[2025-03-12T04:42:41.289+0000] {local_task_job_runner.py:245} INFO - ::endgroup::
